Workbook

Sheet ابدأ هنا
A1: CMH_01
A2: CONVERA — CONtract OVERsight & governAnce
B4: 📊 موجز المشروع — مؤشرات سريعة
B5: قيمة العقد (شامل ض) | C5: إجمالي البنود | D5: مطالبات معتمدة | E5: نسبة الإنجاز % | F5: حد 10% المستخدم
B6: =العقد!I2 -> 65767203 | C6: =COUNTA('بنود العقد'!B2:B388) -> 387 | D6: =COUNTIF(المطالبات!O3:O38,"معتمدة") -> 21 | E6: =IFERROR(MIN(SUMIF(المطالبات!O3:O38,"معتمدة",المطالبات!M3:M38)/العقد!I2*100, 100), 0) -> 98.994174 | F6: ='أوامر التغيير'!B4 -> 9.2184908
B8: 📁 معلومات المشروع
B9: كود المشروع | C9: =العقد!A2 -> CMH_01-C01
B10: اسم المشروع | C10: مشروع تأهيل مقر الوزارة بالعليا
B11: نوع العقد | C11: =العقد!D2 -> إنشاءات
B12: المقاول | C12: شركة الخليج المتطورة للمقاولات
B13: قيمة العقد (شامل ض) | C13: =العقد!I2 -> 65767203
B14: تاريخ البدء | C14: =العقد!J2 -> 44873
B15: تاريخ الانتهاء | C15: =العقد!K2 -> 45323
B16: حالة العقد | C16: =العقد!N2 -> نشط
B17: حد أوامر التغيير (10%) | C17: =العقد!I2*0.1 -> 6576720.3
B19: 📑 فهرس الصفحات (انقر للانتقال)
B20: الصفحة | C20: الوصف
B21: =HYPERLINK("#'العقد'!A1","العقد") -> العقد | C21: بيانات العقد الأساسية والمالية
B22: =HYPERLINK("#'بنود العقد'!A1","بنود العقد") -> بنود العقد | C22: جدول الكميات
B23: =HYPERLINK("#'المطالبات'!A1","المطالبات") -> المطالبات | C23: سجل المطالبات
B24: =HYPERLINK("#'بنود المطالبات'!A1","بنود المطالبات") -> بنود المطالبات | C24: بنود كل مطالبة مع تقدم تراكمي
B25: =HYPERLINK("#'الملخص التراكمي'!A1","الملخص التراكمي") -> الملخص التراكمي | C25: لوحة متابعة التقدم التراكمي لكل بند
B26: =HYPERLINK("#'أوامر التغيير'!A1","أوامر التغيير") -> أوامر التغيير | C26: أوامر التغيير + لوحة حد 10%
B27: =HYPERLINK("#'بنود أوامر التغيير'!A1","بنود أوامر التغيير") -> بنود أوامر التغيير | C27: البنود التفصيلية + استحداث بند جديد
B28: =HYPERLINK("#'سجل الحركة'!A1","سجل الحركة") -> سجل الحركة | C28: تتبع تحولات المطالبات بين المراحل الستة
B29: =HYPERLINK("#'المستخدمون'!A1","المستخدمون") -> المستخدمون | C29: قائمة المستخدمين بالأدوار الستة
B30: =HYPERLINK("#'الجاهزية'!A1","الجاهزية") -> الجاهزية | C30: لوحة فحص جاهزية البيانات للترحيل
B32: 🎨 دليل الألوان والإشارات
C33: أولوية عالية — حقل مطلوب (لا يمكن تخطيه)
C34: تعبئة ثانوية — حقل اختياري
C35: قيمة تلقائية — يمنع التعديل اليدوي
C36: صف مثال توضيحي — يمكن حذفه عند البدء
C37: حالة معتمدة / تقدم 100%
C38: تنبيه تجاوز / حالة مرتجعة أو مرفوضة
C39: تحذير 90% / حالة بانتظار اعتماد
C40: حالة عند التدقيق
B42: 📌 خطوات الاستخدام (1 → 8)
B43: 1) ابدأ بصفحة 'العقد' — عبّئ بيانات العقد الأساسية (نوع العقد من القائمة)
B44: 2) صفحة 'بنود العقد' — أدخل البنود مع التخصص ونوع البند، الكود يُولَّد آلياً
B45: 3) صفحة 'المستخدمون' — سجّل أدوار الفريق الستة (مقاول → معتمد نهائي)
...

Sheet العقد
A1: كود العقد | B1: اسم المشروع | C1: رقم العقد (اعتماد) | D1: نوع العقد | E1: المقاول | F1: قيمة العقد (بدون ض.م) | G1: نسبة ض.ق.م % | H1: قيمة ض.ق.م (تلقائي) | I1: الإجمالي شامل الضريبة (تلقائي) | J1: تاريخ البدء | K1: تاريخ الانتهاء | L1: المدة (أشهر) | M1: نسبة الاستقطاع % | N1: حالة العقد
A2: CMH_01-C01 | B2: مشروع تأهيل مقر الوزارة بالعليا | C2: 220339524310 | D2: إنشاءات | E2: شركة الخليج المتطورة للمقاولات | F2: 57188872 | G2: 15 | H2: =IF(F2<>"", F2*G2/100, "") -> 8578330.8 | I2: =IF(F2<>"", F2+H2, "") -> 65767203 | J2: 44873 | K2: 45323 | L2: =IF(AND(J2<>"",K2<>""), DATEDIF(J2,K2,"M"), "") -> 14 | M2: 10 | N2: نشط

Sheet بنود العقد
A1: رقم البند | B1: وصف البند | C1: التخصص | D1: الوحدة | E1: سعر الوحدة | F1: الكمية التعاقدية | G1: إجمالي البند (تلقائي) | H1: نموذج التقدم | I1: كود البند (تلقائي) | J1: رمز التخصص (تلقائي) | K1: نوع البند
A2: 1 | B2: توريد وتركيب نظام إنذار حريق — مثال | C2: سلامة وإطفاء | D2: عدد | E2: 45000 | F2: 50 | G2: 2250000 | H2: عددي | I2: =IF(AND(B2<>"", J2<>""), "CMH_01-" & J2 & "-" & TEXT(A2, "000"), "") -> CMH_01-FF-001 | J2: =IFERROR(VLOOKUP(C2, مراجع!$A$3:$B$14, 2, FALSE), "") -> FF | K2: مقاولات
A3: 1 | B3: تشتمل على أعمال الهدم وإلإزالة والترحيل داخل أدوار المبنى والسعر يشمل نقل المخلفات الغير صالحه للمقالب العموميه ونقل المخلفات الصالحه لمخازن الجهه المالكه.Ref drawing: 07-MRA-DD-(as per floor number)-AR-001هدم وإزالة الجدران وتشمل جميع أنواع جدران الطوب والقواطع الجبسية و الخشبية و الزجاجية بحسب المخططات المعتمدة وتعليمات المهندس المشرف. | C3: معماري | D3: م2 | E3: 18 | F3: 17900 | G3: =IF(AND(E3<>"",F3<>""), E3*F3, "") -> 322200 | H3: نسبة مئوية | I3: =IF(AND(B3<>"", J3<>""), "CMH_01-" & J3 & "-" & TEXT(A3, "000"), "") -> CMH_01-A-001 | J3: =IFERROR(VLOOKUP(C3, مراجع!$A$3:$B$14, 2, FALSE), "") -> A | K3: مقاولات
A4: 2 | B4: تشتمل على أعمال الهدم وإلإزالة والترحيل داخل أدوار المبنى والسعر يشمل نقل المخلفات الغير صالحه للمقالب العموميه ونقل المخلفات الصالحه لمخازن الجهه المالكه.Ref drawing: 07-MRA-DD-(as per floor number)-AR-هدم وإزالة تشطيبات رخام أو بلاط بورسلان أو سيراميك للأرضيات والجدران الحالية بحسب المخططات المعتمدة وتعليمات المهندس المشرف. | C4: معماري | D4: م2 | E4: 14.5 | F4: 10362 | G4: =IF(AND(E4<>"",F4<>""), E4*F4, "") -> 150249 | H4: نسبة مئوية | I4: =IF(AND(B4<>"", J4<>""), "CMH_01-" & J4 & "-" & TEXT(A4, "000"), "") -> CMH_01-A-002 | J4: =IFERROR(VLOOKUP(C4, مراجع!$A$3:$B$14, 2, FALSE), "") -> A | K4: مقاولات
A5: 3 | B5: تشتمل على أعمال الهدم وإلإزالة والترحيل داخل أدوار المبنى والسعر يشمل نقل المخلفات الغير صالحه للمقالب العموميه ونقل المخلفات الصالحه لمخازن الجهه المالكهRef drawing: 07-MRA-DD-(as per floor number)-AR-001هدم وإزالة تشطيبات الأسقف المستعارة الحالية بما تشمل أسقف جبسية وبلاطات صناعية وأسقف معدنية بحسب المخططات المعتمدة وتعليمات المهندس المشرف. | C5: معماري | D5: م2 | E5: 8.5 | F5: 18420 | G5: =IF(AND(E5<>"",F5<>""), E5*F5, "") -> 156570 | H5: نسبة مئوية | I5: =IF(AND(B5<>"", J5<>""), "CMH_01-" & J5 & "-" & TEXT(A5, "000"), "") -> CMH_01-A-003 | J5: =IFERROR(VLOOKUP(C5, مراجع!$A$3:$B$14, 2, FALSE), "") -> A | K5: مقاولات
A6: 4 | B6: صبة خرسانية مع شبكة حديد بقطر 8 مم بأبعاد 10*10 سم مخدومة بالمسطرين والقدة لتعطي سطحا ناعما في الفناء الوسطي. ويشمل السعر الدفان وأي مواد أو أعمال يتطلبها تنفيذ العمل حسب المواصفات والمخططات وتعليمات المهندس المشرف. | C6: مدني | D6: م3 | E6: 540 | F6: 6 | G6: =IF(AND(E6<>"",F6<>""), E6*F6, "") -> 3240 | H6: نسبة مئوية | I6: =IF(AND(B6<>"", J6<>""), "CMH_01-" & J6 & "-" & TEXT(A6, "000"), "") -> CMH_01-C-004 | J6: =IFERROR(VLOOKUP(C6, مراجع!$A$3:$B$14, 2, FALSE), "") -> C | K6: مقاولات
A7: 5 | B7: صبة أسمنتية كطبقة حماية للعزل في الأماكن الرطبة. ويشمل السعر وأي مواد أو أعمال يتطلبها تنفيذ العمل حسب المواصفات والمخططات وتعليمات المهندس المشرف. | C7: مدني | D7: م3 | E7: 366 | F7: 1345 | G7: =IF(AND(E7<>"",F7<>""), E7*F7, "") -> 492270 | H7: نسبة مئوية | I7: =IF(AND(B7<>"", J7<>""), "CMH_01-" & J7 & "-" & TEXT(A7, "000"), "") -> CMH_01-C-005 | J7: =IFERROR(VLOOKUP(C7, مراجع!$A$3:$B$14, 2, FALSE), "") -> C | K7: مقاولات
A8: 6 | B8: توريد وبناء مباني من البلوك مقاوم للحريق شاملا المونة والفواصل وأربطة التثبيت والتسليح الرأسي وعتبات جميع الفتحات وعزل الجدران المزدوجة المفرّغة والمكملات ويتم توريد البلوك بالموقع على قواعد خشبية مغطاه بالبلاستيك ويستمر على هذه الحالة حتى يبدأ استخدامه للبناء على أن يكون ذو ابعاد بطول 40سم وسماكة حسب المطلوب وارتفاع 20سم وان تكون صلد سليم نظيف وذو زوايا خارجية قائمة يستعمل لبناء الحوائط حسب ما هو موضح بالمخططات مع التكحيل ويكون مطابق للمواصفات حسب النوعيه المطلوبة والسعر يشمل كل مايلزم للبناء من البلوك الكامل والقطع الخاصة سواء 5.0 أو 25.0 ، كذلك القطع الخاصة بتمديد المواسير بحيث لا يتم تكسير البلوك أثناء الاستخدام للبناء على الأطلاق ، بالإضافة إلى كافة المواد والاكسسوارات والسقايل واستعمال الشبك الممدد والتسليح بواسطة خوابير معدنية والمرابط المعدنية ويشمل السعر أي مواد أو أعمال يتطلبها استكمال العمل حسب المواصفات القسم Ref drawing: 07-MRA-DD-(as per floor number) وتعليمات المهندس المشرف 04200Ar-100 | C8: معماري | D8: م2 | E8: 150 | F8: 450 | G8: =IF(AND(E8<>"",F8<>""), E8*F8, "") -> 67500 | H8: نسبة مئوية | I8: =IF(AND(B8<>"", J8<>""), "CMH_01-" & J8 & "-" & TEXT(A8, "000"), "") -> CMH_01-A-006 | J8: =IFERROR(VLOOKUP(C8, مراجع!$A$3:$B$14, 2, FALSE), "") -> A | K8: مقاولات
A9: 7 | B9: توريد وبناء مباني من البلوك مقاوم للحريق شاملا المونة والفواصل وأربطة التثبيت والتسليح الرأسي وعتبات جميع الفتحات وعزل الجدران المزدوجة المفرّغة والمكملات ويتم توريد البلوك بالموقع علىقواعد خشبية مغطاه بالبلاستيك ويستمر على هذه الحالة حتى يبدأ استخدامه للبناء على أن يكون ذو ابعاد بطول 40سم وسماكة حسب المطلوب وارتفاع 20سم وان تكون صلد سليم نظيف وذو زوايا خارجية قائمة يستعمل لبناء الحوائط حسب ما هو موضح بالمخططات مع التكحيل ويكون مطابق للمواصفات حسب النوعيه المطلوبة والسعر يشمل كل مايلزم للبناء من البلوك الكامل والقطع الخاصة سواء 5.0 أو 25.0 ، كذلك القطع الخاصة بتمديد المواسير بحيث لا يتم تكسير البلوك أثناء الاستخدام للبناء على الأطلاق ، بالإضافة إلى كافة المواد والاكسسوارات والسقايل واستعمال الشبك الممدد والتسليح بواسطة خوابير معدنية والمرابط المعدنية ويشمل السعر أي مواد أو أعمال يتطلبها استكمال العمل حسب المواصفات القسمRef drawing: 07-MRA-DD-(as per floor number) وتعليمات المهندس المشرف 04200-Ar-100 | C9: معماري | D9: م2 | E9: 150 | F9: 76 | G9: =IF(AND(E9<>"",F9<>""), E9*F9, "") -> 11400 | H9: نسبة مئوية | I9: =IF(AND(B9<>"", J9<>""), "CMH_01-" & J9 & "-" & TEXT(A9, "000"), "") -> CMH_01-A-007 | J9: =IFERROR(VLOOKUP(C9, مراجع!$A$3:$B$14, 2, FALSE), "") -> A | K9: مقاولات
A10: 8 | B10: توريد وتركيب درابزين من الزجاج السيكوريت سمك 12 مم مثبت بالارضيات للفناء الداخلي المفتوح بارتفاع 600مم شاملاً إطار الدرابزين من الالمنيوم )u-channel( مقاس 40مم × 30مم ثخانة2مم )لون اسود 9005RAL ( ويشمل السعر الاكسسوارات وأي مواد أو أعمال يتطلبها تشطيب العمل حسب المواصفات والمخططات. | C10: معماري | D10: م.ط | E10: 540 | F10: 20 | G10: =IF(AND(E10<>"",F10<>""), E10*F10, "") -> 10800 | H10: نسبة مئوية | I10: =IF(AND(B10<>"", J10<>""), "CMH_01-" & J10 & "-" & TEXT(A10, "000"), "") -> CMH_01-A-008 | J10: =IFERROR(VLOOKUP(C10, مراجع!$A$3:$B$14, 2, FALSE), "") -> A | K10: مقاولات
A11: 9 | B11: توريد وتركيب درابزين من الزجاج السيكوريت سمك 12 مم مثبت بالارضيات للفناء الوسطي الاساسي 1100 مم شاملاإًطار الدرابزين من الالمنيوم )u-channel( مقاس80مم × 40مم )لون اسود 9005RAL ( ويشمل السعر الاكسسوارات وأي مواد أو أعمال يتطلبها تشطيب العمل حسب المواصفات والمخططات وتعليمات المهندس المشرف | C11: معماري | D11: م.ط | E11: 540 | F11: 20 | G11: =IF(AND(E11<>"",F11<>""), E11*F11, "") -> 10800 | H11: نسبة مئوية | I11: =IF(AND(B11<>"", J11<>""), "CMH_01-" & J11 & "-" & TEXT(A11, "000"), "") -> CMH_01-A-009 | J11: =IFERROR(VLOOKUP(C11, مراجع!$A$3:$B$14, 2, FALSE), "") -> A | K11: مقاولات
A12: 10 | B12: إعادة دهان هاندرايل من الحديد بالايبوكسي ويشمل ازالة الدهان القديم بالترميل )Sand Plasting( حسب المواصفات والاصول الفنيه وتعليمات المهندس المشرف. | C12: معماري | D12: م.ط | E12: 42 | F12: 420 | G12: =IF(AND(E12<>"",F12<>""), E12*F12, "") -> 17640 | H12: نسبة مئوية | I12: =IF(AND(B12<>"", J12<>""), "CMH_01-" & J12 & "-" & TEXT(A12, "000"), "") -> CMH_01-A-010 | J12: =IFERROR(VLOOKUP(C12, مراجع!$A$3:$B$14, 2, FALSE), "") -> A | K12: مقاولات
A13: 11 | B13: تجديد وترميم ودهان وتلميع البوابات الحديدية الرئيسية في المدخل الغربي )مدخل الوزير( والبوابة الرئيسية في المدخل الشمالي )مدخل الموظفين( وتشمل الأعمال ما يلي:تجديد وترميم أبواب الحديد، سنفرة الأبواب، عمل طبقة تأسيس ناري للأبواب، تعشيقة الأبواب مع تلميع الزخرفة، دهان وتلميع الأجزاء نهاية الزخرفة بمواد أيبوكسي + دهان ماء الذهب المركز للأطراف الخارجية + تلميع خارجي بمادة البوليريثان، المحافظة على نظافة المكان وإزالة المخلفات. حسب الاصول الفنيه وتعليمات المهندس المشرف | C13: معماري | D13: م.ط | E13: 12000 | F13: 2 | G13: =IF(AND(E13<>"",F13<>""), E13*F13, "") -> 24000 | H13: نسبة مئوية | I13: =IF(AND(B13<>"", J13<>""), "CMH_01-" & J13 & "-" & TEXT(A13, "000"), "") -> CMH_01-A-011 | J13: =IFERROR(VLOOKUP(C13, مراجع!$A$3:$B$14, 2, FALSE), "") -> A | K13: مقاولات
A14: 12 | B14: توريد وتركيب اسقف شبكة حديد مش )طلاء بودرة بالفرن لون اسود( سماكة 2 ملم مع تيوب حديد ابعاد 4*8 سم وسماكة 3ملم ، مثبتة بنظام تعليق متصلة بالسقف الخرساني حسب الرسومات والمناظير وتعليمات المهندس المشرف.Ref drawing: 07-MRA-DD-G.F-AR-200 | C14: معماري | D14: م2 | E14: 360 | F14: 27 | G14: =IF(AND(E14<>"",F14<>""), E14*F14, "") -> 9720 | H14: نسبة مئوية | I14: =IF(AND(B14<>"", J14<>""), "CMH_01-" & J14 & "-" & TEXT(A14, "000"), "") -> CMH_01-A-012 | J14: =IFERROR(VLOOKUP(C14, مراجع!$A$3:$B$14, 2, FALSE), "") -> A | K14: مقاولات
... A388: 386 | B388: توريد وتركيب فيش صناعى 32 أمبير 2P+E | C388: كهرباء | D388: عدد | E388: 190.8 | F388: 0 | G388: =IF(AND(E388<>"",F388<>""), E388*F388, "") -> 0 | H388: نسبة مئوية | I388: =IF(AND(B388<>"", J388<>""), "CMH_01-" & J388 & "-" & TEXT(A388, "000"), "") -> CMH_01-EE-386 | J388: =IFERROR(VLOOKUP(C388, مراجع!$A$3:$B$14, 2, FALSE), "") -> EE | K388: مقاولات

Sheet المطالبات
A1: م | B1: كود العقد | C1: رقم المطالبة الرسمي | D1: نوع المطالبة | E1: الفترة من | F1: الفترة إلى | G1: مبلغ البنود (تلقائي) | H1: نسبة الأداء % | I1: المبلغ بعد الأداء (تلقائي) | J1: الاستقطاع (تلقائي) | K1: صافي المبلغ (تلقائي) | L1: ض.ق.م (تلقائي) | M1: الإجمالي المستحق (تلقائي) | N1: تراكمي المعتمد (تلقائي) | O1: الحالة | P1: ملاحظات | Q1: معرّف خارجي (External Ref)
A2: 1 | B2: CMH_03-C01 | C2: 3100012345 | D2: بنود فقط | E2: 2024-05-01 | F2: 2024-05-31 | G2: 850000 | H2: 100 | I2: 850000 | J2: 42500 | K2: 807500 | L2: 121125 | M2: 928625 | N2: 928625 | O2: معتمدة | P2: المطالبة الأولى
A3: 1 | B3: =العقد!A2 -> CMH_01-C01 | C3: 230302028960 | D3: بنود فقط | E3: 44873 | F3: 44934 | G3: =SUMIF('بنود المطالبات'!B$3:B$1805, A3, 'بنود المطالبات'!K$3:K$1805) -> 643229.83 | H3: 100 | I3: =IFERROR(IF(G3<>0, G3*IF(H3<>"",H3,100)/100, 0), 0) -> 643229.83 | J3: =IFERROR(IF(I3<>0, I3*IF(العقد!$M$2<>"",العقد!$M$2,0)/100, 0), 0) -> 64322.983 | K3: =I3-J3 -> 578906.85 | L3: =IFERROR(IF(K3<>0, K3*IF(العقد!$G$2<>"",العقد!$G$2,15)/100, 0), 0) -> 86836.027 | M3: =K3+L3 -> 665742.87 | N3: =SUMPRODUCT((O$3:O3="معتمدة")*M$3:M3) -> 665742.87 | O3: معتمدة | Q3: =IF(C3<>"", "CMH_01-CLM-" & TEXT(A3, "000"), "") -> CMH_01-CLM-001
A4: 2 | B4: =العقد!A2 -> CMH_01-C01 | C4: 230502047363 | D4: بنود فقط | E4: 44934 | F4: 44993 | G4: =SUMIF('بنود المطالبات'!B$3:B$1805, A4, 'بنود المطالبات'!K$3:K$1805) -> 555052.44 | H4: 100 | I4: =IFERROR(IF(G4<>0, G4*IF(H4<>"",H4,100)/100, 0), 0) -> 555052.44 | J4: =IFERROR(IF(I4<>0, I4*IF(العقد!$M$2<>"",العقد!$M$2,0)/100, 0), 0) -> 55505.244 | K4: =I4-J4 -> 499547.2 | L4: =IFERROR(IF(K4<>0, K4*IF(العقد!$G$2<>"",العقد!$G$2,15)/100, 0), 0) -> 74932.079 | M4: =K4+L4 -> 574479.28 | N4: =SUMPRODUCT((O$3:O4="معتمدة")*M$3:M4) -> 1240222.1 | O4: معتمدة | Q4: =IF(C4<>"", "CMH_01-CLM-" & TEXT(A4, "000"), "") -> CMH_01-CLM-002
A5: 3 | B5: =العقد!A2 -> CMH_01-C01 | C5: 230602216686 | D5: بنود فقط | E5: 44993 | F5: 45081 | G5: =SUMIF('بنود المطالبات'!B$3:B$1805, A5, 'بنود المطالبات'!K$3:K$1805) -> 1330080.5 | H5: 100 | I5: =IFERROR(IF(G5<>0, G5*IF(H5<>"",H5,100)/100, 0), 0) -> 1330080.5 | J5: =IFERROR(IF(I5<>0, I5*IF(العقد!$M$2<>"",العقد!$M$2,0)/100, 0), 0) -> 133008.05 | K5: =I5-J5 -> 1197072.5 | L5: =IFERROR(IF(K5<>0, K5*IF(العقد!$G$2<>"",العقد!$G$2,15)/100, 0), 0) -> 179560.87 | M5: =K5+L5 -> 1376633.3 | N5: =SUMPRODUCT((O$3:O5="معتمدة")*M$3:M5) -> 2616855.5 | O5: معتمدة | Q5: =IF(C5<>"", "CMH_01-CLM-" & TEXT(A5, "000"), "") -> CMH_01-CLM-003
A6: 4 | B6: =العقد!A2 -> CMH_01-C01 | C6: 230802167393 | D6: بنود فقط | E6: 45081 | F6: 45111 | G6: =SUMIF('بنود المطالبات'!B$3:B$1805, A6, 'بنود المطالبات'!K$3:K$1805) -> 758335.01 | H6: 100 | I6: =IFERROR(IF(G6<>0, G6*IF(H6<>"",H6,100)/100, 0), 0) -> 758335.01 | J6: =IFERROR(IF(I6<>0, I6*IF(العقد!$M$2<>"",العقد!$M$2,0)/100, 0), 0) -> 75833.501 | K6: =I6-J6 -> 682501.51 | L6: =IFERROR(IF(K6<>0, K6*IF(العقد!$G$2<>"",العقد!$G$2,15)/100, 0), 0) -> 102375.23 | M6: =K6+L6 -> 784876.73 | N6: =SUMPRODUCT((O$3:O6="معتمدة")*M$3:M6) -> 3401732.2 | O6: معتمدة
A7: 5 | B7: =العقد!A2 -> CMH_01-C01 | C7: 230902137329 | D7: بنود فقط | E7: 45111 | F7: 45171 | G7: =SUMIF('بنود المطالبات'!B$3:B$1805, A7, 'بنود المطالبات'!K$3:K$1805) -> 3060076.1 | H7: 100 | I7: =IFERROR(IF(G7<>0, G7*IF(H7<>"",H7,100)/100, 0), 0) -> 3060076.1 | J7: =IFERROR(IF(I7<>0, I7*IF(العقد!$M$2<>"",العقد!$M$2,0)/100, 0), 0) -> 306007.61 | K7: =I7-J7 -> 2754068.5 | L7: =IFERROR(IF(K7<>0, K7*IF(العقد!$G$2<>"",العقد!$G$2,15)/100, 0), 0) -> 413110.28 | M7: =K7+L7 -> 3167178.8 | N7: =SUMPRODUCT((O$3:O7="معتمدة")*M$3:M7) -> 6568911 | O7: معتمدة | Q7: =IF(C7<>"", "CMH_01-CLM-" & TEXT(A7, "000"), "") -> CMH_01-CLM-005
A8: 6 | B8: =العقد!A2 -> CMH_01-C01 | C8: 231002332498 | D8: بنود فقط | E8: 45171 | F8: 45246 | G8: =SUMIF('بنود المطالبات'!B$3:B$1805, A8, 'بنود المطالبات'!K$3:K$1805) -> 1525725 | H8: 100 | I8: =IFERROR(IF(G8<>0, G8*IF(H8<>"",H8,100)/100, 0), 0) -> 1525725 | J8: =IFERROR(IF(I8<>0, I8*IF(العقد!$M$2<>"",العقد!$M$2,0)/100, 0), 0) -> 152572.5 | K8: =I8-J8 -> 1373152.5 | L8: =IFERROR(IF(K8<>0, K8*IF(العقد!$G$2<>"",العقد!$G$2,15)/100, 0), 0) -> 205972.88 | M8: =K8+L8 -> 1579125.4 | N8: =SUMPRODUCT((O$3:O8="معتمدة")*M$3:M8) -> 8148036.4 | O8: معتمدة | Q8: =IF(C8<>"", "CMH_01-CLM-" & TEXT(A8, "000"), "") -> CMH_01-CLM-006
A9: 7 | B9: =العقد!A2 -> CMH_01-C01 | C9: 240102169624 | D9: بنود فقط | E9: 45246 | F9: 45306 | G9: =SUMIF('بنود المطالبات'!B$3:B$1805, A9, 'بنود المطالبات'!K$3:K$1805) -> 2904825.8 | H9: 100 | I9: =IFERROR(IF(G9<>0, G9*IF(H9<>"",H9,100)/100, 0), 0) -> 2904825.8 | J9: =IFERROR(IF(I9<>0, I9*IF(العقد!$M$2<>"",العقد!$M$2,0)/100, 0), 0) -> 290482.58 | K9: =I9-J9 -> 2614343.2 | L9: =IFERROR(IF(K9<>0, K9*IF(العقد!$G$2<>"",العقد!$G$2,15)/100, 0), 0) -> 392151.48 | M9: =K9+L9 -> 3006494.7 | N9: =SUMPRODUCT((O$3:O9="معتمدة")*M$3:M9) -> 11154531 | O9: معتمدة | Q9: =IF(C9<>"", "CMH_01-CLM-" & TEXT(A9, "000"), "") -> CMH_01-CLM-007
A10: 8 | B10: =العقد!A2 -> CMH_01-C01 | C10: 240202247790 | D10: بنود فقط | E10: 45306 | F10: 45339 | G10: =SUMIF('بنود المطالبات'!B$3:B$1805, A10, 'بنود المطالبات'!K$3:K$1805) -> 4089443.7 | H10: 100 | I10: =IFERROR(IF(G10<>0, G10*IF(H10<>"",H10,100)/100, 0), 0) -> 4089443.7 | J10: =IFERROR(IF(I10<>0, I10*IF(العقد!$M$2<>"",العقد!$M$2,0)/100, 0), 0) -> 408944.37 | K10: =I10-J10 -> 3680499.3 | L10: =IFERROR(IF(K10<>0, K10*IF(العقد!$G$2<>"",العقد!$G$2,15)/100, 0), 0) -> 552074.89 | M10: =K10+L10 -> 4232574.2 | N10: =SUMPRODUCT((O$3:O10="معتمدة")*M$3:M10) -> 15387105 | O10: معتمدة | Q10: =IF(C10<>"", "CMH_01-CLM-" & TEXT(A10, "000"), "") -> CMH_01-CLM-008
A11: 9 | B11: =العقد!A2 -> CMH_01-C01 | C11: 240402029618 | D11: بنود فقط | E11: 45339 | F11: 45384 | G11: =SUMIF('بنود المطالبات'!B$3:B$1805, A11, 'بنود المطالبات'!K$3:K$1805) -> 1893689.6 | H11: 100 | I11: =IFERROR(IF(G11<>0, G11*IF(H11<>"",H11,100)/100, 0), 0) -> 1893689.6 | J11: =IFERROR(IF(I11<>0, I11*IF(العقد!$M$2<>"",العقد!$M$2,0)/100, 0), 0) -> 189368.96 | K11: =I11-J11 -> 1704320.6 | L11: =IFERROR(IF(K11<>0, K11*IF(العقد!$G$2<>"",العقد!$G$2,15)/100, 0), 0) -> 255648.1 | M11: =K11+L11 -> 1959968.7 | N11: =SUMPRODUCT((O$3:O11="معتمدة")*M$3:M11) -> 17347074 | O11: معتمدة | Q11: =IF(C11<>"", "CMH_01-CLM-" & TEXT(A11, "000"), "") -> CMH_01-CLM-009
A12: 10 | B12: =العقد!A2 -> CMH_01-C01 | C12: 240402175547 | D12: بنود فقط | E12: 45384 | F12: 45407 | G12: =SUMIF('بنود المطالبات'!B$3:B$1805, A12, 'بنود المطالبات'!K$3:K$1805) -> 1711342 | H12: 100 | I12: =IFERROR(IF(G12<>0, G12*IF(H12<>"",H12,100)/100, 0), 0) -> 1711342 | J12: =IFERROR(IF(I12<>0, I12*IF(العقد!$M$2<>"",العقد!$M$2,0)/100, 0), 0) -> 171134.2 | K12: =I12-J12 -> 1540207.8 | L12: =IFERROR(IF(K12<>0, K12*IF(العقد!$G$2<>"",العقد!$G$2,15)/100, 0), 0) -> 231031.16 | M12: =K12+L12 -> 1771238.9 | N12: =SUMPRODUCT((O$3:O12="معتمدة")*M$3:M12) -> 19118313 | O12: معتمدة | Q12: =IF(C12<>"", "CMH_01-CLM-" & TEXT(A12, "000"), "") -> CMH_01-CLM-010
A13: 11 | B13: =العقد!A2 -> CMH_01-C01 | C13: 240602053573 | D13: بنود فقط | E13: 45407 | F13: 45448 | G13: =SUMIF('بنود المطالبات'!B$3:B$1805, A13, 'بنود المطالبات'!K$3:K$1805) -> 3969678.1 | H13: 100 | I13: =IFERROR(IF(G13<>0, G13*IF(H13<>"",H13,100)/100, 0), 0) -> 3969678.1 | J13: =IFERROR(IF(I13<>0, I13*IF(العقد!$M$2<>"",العقد!$M$2,0)/100, 0), 0) -> 396967.81 | K13: =I13-J13 -> 3572710.3 | L13: =IFERROR(IF(K13<>0, K13*IF(العقد!$G$2<>"",العقد!$G$2,15)/100, 0), 0) -> 535906.54 | M13: =K13+L13 -> 4108616.8 | N13: =SUMPRODUCT((O$3:O13="معتمدة")*M$3:M13) -> 23226930 | O13: معتمدة | Q13: =IF(C13<>"", "CMH_01-CLM-" & TEXT(A13, "000"), "") -> CMH_01-CLM-011
A14: 12 | B14: =العقد!A2 -> CMH_01-C01 | C14: 240702195001 | D14: بنود فقط | E14: 45448 | F14: 45481 | G14: =SUMIF('بنود المطالبات'!B$3:B$1805, A14, 'بنود المطالبات'!K$3:K$1805) -> 1577832.6 | H14: 100 | I14: =IFERROR(IF(G14<>0, G14*IF(H14<>"",H14,100)/100, 0), 0) -> 1577832.6 | J14: =IFERROR(IF(I14<>0, I14*IF(العقد!$M$2<>"",العقد!$M$2,0)/100, 0), 0) -> 157783.26 | K14: =I14-J14 -> 1420049.3 | L14: =IFERROR(IF(K14<>0, K14*IF(العقد!$G$2<>"",العقد!$G$2,15)/100, 0), 0) -> 213007.4 | M14: =K14+L14 -> 1633056.7 | N14: =SUMPRODUCT((O$3:O14="معتمدة")*M$3:M14) -> 24859986 | O14: معتمدة | Q14: =IF(C14<>"", "CMH_01-CLM-" & TEXT(A14, "000"), "") -> CMH_01-CLM-012
A15: 13 | B15: =العقد!A2 -> CMH_01-C01 | C15: 240902011858 | D15: بنود فقط | E15: 45481 | F15: 45528 | G15: =SUMIF('بنود المطالبات'!B$3:B$1805, A15, 'بنود المطالبات'!K$3:K$1805) -> 1634218.6 | H15: 100 | I15: =IFERROR(IF(G15<>0, G15*IF(H15<>"",H15,100)/100, 0), 0) -> 1634218.6 | J15: =IFERROR(IF(I15<>0, I15*IF(العقد!$M$2<>"",العقد!$M$2,0)/100, 0), 0) -> 163421.86 | K15: =I15-J15 -> 1470796.7 | L15: =IFERROR(IF(K15<>0, K15*IF(العقد!$G$2<>"",العقد!$G$2,15)/100, 0), 0) -> 220619.51 | M15: =K15+L15 -> 1691416.2 | N15: =SUMPRODUCT((O$3:O15="معتمدة")*M$3:M15) -> 26551403 | O15: معتمدة | Q15: =IF(C15<>"", "CMH_01-CLM-" & TEXT(A15, "000"), "") -> CMH_01-CLM-013
A16: 14 | B16: =العقد!A2 -> CMH_01-C01 | C16: 241002110633 | D16: بنود فقط | E16: 45528 | F16: 45570 | G16: =SUMIF('بنود المطالبات'!B$3:B$1805, A16, 'بنود المطالبات'!K$3:K$1805) -> 5426451.2 | H16: 100 | I16: =IFERROR(IF(G16<>0, G16*IF(H16<>"",H16,100)/100, 0), 0) -> 5426451.2 | J16: =IFERROR(IF(I16<>0, I16*IF(العقد!$M$2<>"",العقد!$M$2,0)/100, 0), 0) -> 542645.12 | K16: =I16-J16 -> 4883806 | L16: =IFERROR(IF(K16<>0, K16*IF(العقد!$G$2<>"",العقد!$G$2,15)/100, 0), 0) -> 732570.91 | M16: =K16+L16 -> 5616376.9 | N16: =SUMPRODUCT((O$3:O16="معتمدة")*M$3:M16) -> 32167780 | O16: معتمدة | Q16: =IF(C16<>"", "CMH_01-CLM-" & TEXT(A16, "000"), "") -> CMH_01-CLM-014
A17: 15 | B17: =العقد!A2 -> CMH_01-C01 | C17: 241102111582 | D17: بنود فقط | G17: =SUMIF('بنود المطالبات'!B$3:B$1805, A17, 'بنود المطالبات'!K$3:K$1805) -> 0 | H17: 100 | I17: =IFERROR(IF(G17<>0, G17*IF(H17<>"",H17,100)/100, 0), 0) -> 0 | J17: =IFERROR(IF(I17<>0, I17*IF(العقد!$M$2<>"",العقد!$M$2,0)/100, 0), 0) -> 0 | K17: =I17-J17 -> 0 | L17: =IFERROR(IF(K17<>0, K17*IF(العقد!$G$2<>"",العقد!$G$2,15)/100, 0), 0) -> 0 | M17: =K17+L17 -> 0 | N17: =SUMPRODUCT((O$3:O17="معتمدة")*M$3:M17) -> 32167780 | O17: معتمدة | Q17: =IF(C17<>"", "CMH_01-CLM-" & TEXT(A17, "000"), "") -> CMH_01-CLM-015
A18: 16 | B18: =العقد!A2 -> CMH_01-C01 | C18: 241102213835 | D18: بنود فقط | E18: 45570 | F18: 45606 | G18: =SUMIF('بنود المطالبات'!B$3:B$1805, A18, 'بنود المطالبات'!K$3:K$1805) -> 4734576 | H18: 100 | I18: =IFERROR(IF(G18<>0, G18*IF(H18<>"",H18,100)/100, 0), 0) -> 4734576 | J18: =IFERROR(IF(I18<>0, I18*IF(العقد!$M$2<>"",العقد!$M$2,0)/100, 0), 0) -> 473457.6 | K18: =I18-J18 -> 4261118.4 | L18: =IFERROR(IF(K18<>0, K18*IF(العقد!$G$2<>"",العقد!$G$2,15)/100, 0), 0) -> 639167.76 | M18: =K18+L18 -> 4900286.2 | N18: =SUMPRODUCT((O$3:O18="معتمدة")*M$3:M18) -> 37068066 | O18: معتمدة | Q18: =IF(C18<>"", "CMH_01-CLM-" & TEXT(A18, "000"), "") -> CMH_01-CLM-016
A19: 17 | B19: =العقد!A2 -> CMH_01-C01 | C19: 250302015472 | D19: بنود فقط | E19: 45606 | F19: 45718 | G19: =SUMIF('بنود المطالبات'!B$3:B$1805, A19, 'بنود المطالبات'!K$3:K$1805) -> 10805301 | H19: 100 | I19: =IFERROR(IF(G19<>0, G19*IF(H19<>"",H19,100)/100, 0), 0) -> 10805301 | J19: =IFERROR(IF(I19<>0, I19*IF(العقد!$M$2<>"",العقد!$M$2,0)/100, 0), 0) -> 1080530.1 | K19: =I19-J19 -> 9724771 | L19: =IFERROR(IF(K19<>0, K19*IF(العقد!$G$2<>"",العقد!$G$2,15)/100, 0), 0) -> 1458715.7 | M19: =K19+L19 -> 11183487 | N19: =SUMPRODUCT((O$3:O19="معتمدة")*M$3:M19) -> 48251552 | O19: معتمدة
A20: 18 | B20: =العقد!A2 -> CMH_01-C01 | C20: 250502023877 | D20: بنود فقط | E20: 45718 | F20: 45743 | G20: =SUMIF('بنود المطالبات'!B$3:B$1805, A20, 'بنود المطالبات'!K$3:K$1805) -> 8333499.7 | H20: 100 | I20: =IFERROR(IF(G20<>0, G20*IF(H20<>"",H20,100)/100, 0), 0) -> 8333499.7 | J20: =IFERROR(IF(I20<>0, I20*IF(العقد!$M$2<>"",العقد!$M$2,0)/100, 0), 0) -> 833349.97 | K20: =I20-J20 -> 7500149.7 | L20: =IFERROR(IF(K20<>0, K20*IF(العقد!$G$2<>"",العقد!$G$2,15)/100, 0), 0) -> 1125022.5 | M20: =K20+L20 -> 8625172.2 | N20: =SUMPRODUCT((O$3:O20="معتمدة")*M$3:M20) -> 56876725 | O20: معتمدة
A21: 19 | B21: =العقد!A2 -> CMH_01-C01 | C21: 250702126887 | D21: بنود فقط | E21: 45718 | F21: 45743 | G21: =SUMIF('بنود المطالبات'!B$3:B$1805, A21, 'بنود المطالبات'!K$3:K$1805) -> 3666523.5 | H21: 100 | I21: =IFERROR(IF(G21<>0, G21*IF(H21<>"",H21,100)/100, 0), 0) -> 3666523.5 | J21: =IFERROR(IF(I21<>0, I21*IF(العقد!$M$2<>"",العقد!$M$2,0)/100, 0), 0) -> 366652.35 | K21: =I21-J21 -> 3299871.1 | L21: =IFERROR(IF(K21<>0, K21*IF(العقد!$G$2<>"",العقد!$G$2,15)/100, 0), 0) -> 494980.67 | M21: =K21+L21 -> 3794851.8 | N21: =SUMPRODUCT((O$3:O21="معتمدة")*M$3:M21) -> 60671576 | O21: معتمدة
A22: 20 | B22: =العقد!A2 -> CMH_01-C01 | C22: 250902193001 | D22: بنود فقط | E22: 45718 | F22: 45743 | G22: =SUMIF('بنود المطالبات'!B$3:B$1805, A22, 'بنود المطالبات'!K$3:K$1805) -> 3594042.6 | H22: 100 | I22: =IFERROR(IF(G22<>0, G22*IF(H22<>"",H22,100)/100, 0), 0) -> 3594042.6 | J22: =IFERROR(IF(I22<>0, I22*IF(العقد!$M$2<>"",العقد!$M$2,0)/100, 0), 0) -> 359404.26 | K22: =I22-J22 -> 3234638.4 | L22: =IFERROR(IF(K22<>0, K22*IF(العقد!$G$2<>"",العقد!$G$2,15)/100, 0), 0) -> 485195.75 | M22: =K22+L22 -> 3719834.1 | N22: =SUMPRODUCT((O$3:O22="معتمدة")*M$3:M22) -> 64391411 | O22: معتمدة | Q22: =IF(C22<>"", "CMH_01-CLM-" & TEXT(A22, "000"), "") -> CMH_01-CLM-020
A23: 21 | B23: =العقد!A2 -> CMH_01-C01 | C23: 251102237265 | D23: بنود فقط | E23: 45718 | F23: 45743 | G23: =SUMIF('بنود المطالبات'!B$3:B$1805, A23, 'بنود المطالبات'!K$3:K$1805) -> 690133.76 | H23: 100 | I23: =IFERROR(IF(G23<>0, G23*IF(H23<>"",H23,100)/100, 0), 0) -> 690133.76 | J23: =IFERROR(IF(I23<>0, I23*IF(العقد!$M$2<>"",العقد!$M$2,0)/100, 0), 0) -> 69013.376 | K23: =I23-J23 -> 621120.38 | L23: =IFERROR(IF(K23<>0, K23*IF(العقد!$G$2<>"",العقد!$G$2,15)/100, 0), 0) -> 93168.057 | M23: =K23+L23 -> 714288.44 | N23: =SUMPRODUCT((O$3:O23="معتمدة")*M$3:M23) -> 65105699 | O23: معتمدة
A24: 36 | B24: =العقد!A2 -> CMH_01-C01 | G24: =SUMIF('بنود المطالبات'!B$3:B$1805, A24, 'بنود المطالبات'!K$3:K$1805) -> 0 | H24: 100 | I24: =IFERROR(IF(G24<>0, G24*IF(H24<>"",H24,100)/100, 0), 0) -> 0 | J24: =IFERROR(IF(I24<>0, I24*IF(العقد!$M$2<>"",العقد!$M$2,0)/100, 0), 0) -> 0 | K24: =I24-J24 -> 0 | L24: =IFERROR(IF(K24<>0, K24*IF(العقد!$G$2<>"",العقد!$G$2,15)/100, 0), 0) -> 0 | M24: =K24+L24 -> 0 | N24: =SUMPRODUCT((O$3:O24="معتمدة")*M$3:M24) -> 65105699 | Q24: =IF(C24<>"", "CMH_01-CLM-" & TEXT(A24, "000"), "")
A25: 37 | B25: =العقد!A2 -> CMH_01-C01 | G25: =SUMIF('بنود المطالبات'!B$3:B$1805, A25, 'بنود المطالبات'!K$3:K$1805) -> 0 | H25: 100 | I25: =IFERROR(IF(G25<>0, G25*IF(H25<>"",H25,100)/100, 0), 0) -> 0 | J25: =IFERROR(IF(I25<>0, I25*IF(العقد!$M$2<>"",العقد!$M$2,0)/100, 0), 0) -> 0 | K25: =I25-J25 -> 0 | L25: =IFERROR(IF(K25<>0, K25*IF(العقد!$G$2<>"",العقد!$G$2,15)/100, 0), 0) -> 0 | M25: =K25+L25 -> 0 | N25: =SUMPRODUCT((O$3:O25="معتمدة")*M$3:M25) -> 65105699 | Q25: =IF(C25<>"", "CMH_01-CLM-" & TEXT(A25, "000"), "")
A26: 38 | B26: =العقد!A2 -> CMH_01-C01 | G26: =SUMIF('بنود المطالبات'!B$3:B$1805, A26, 'بنود المطالبات'!K$3:K$1805) -> 0 | H26: 100 | I26: =IFERROR(IF(G26<>0, G26*IF(H26<>"",H26,100)/100, 0), 0) -> 0 | J26: =IFERROR(IF(I26<>0, I26*IF(العقد!$M$2<>"",العقد!$M$2,0)/100, 0), 0) -> 0 | K26: =I26-J26 -> 0 | L26: =IFERROR(IF(K26<>0, K26*IF(العقد!$G$2<>"",العقد!$G$2,15)/100, 0), 0) -> 0 | M26: =K26+L26 -> 0 | N26: =SUMPRODUCT((O$3:O26="معتمدة")*M$3:M26) -> 65105699 | Q26: =IF(C26<>"", "CMH_01-CLM-" & TEXT(A26, "000"), "")
A27: 39 | B27: =العقد!A2 -> CMH_01-C01 | G27: =SUMIF('بنود المطالبات'!B$3:B$1805, A27, 'بنود المطالبات'!K$3:K$1805) -> 0 | H27: 100 | I27: =IFERROR(IF(G27<>0, G27*IF(H27<>"",H27,100)/100, 0), 0) -> 0 | J27: =IFERROR(IF(I27<>0, I27*IF(العقد!$M$2<>"",العقد!$M$2,0)/100, 0), 0) -> 0 | K27: =I27-J27 -> 0 | L27: =IFERROR(IF(K27<>0, K27*IF(العقد!$G$2<>"",العقد!$G$2,15)/100, 0), 0) -> 0 | M27: =K27+L27 -> 0 | N27: =SUMPRODUCT((O$3:O27="معتمدة")*M$3:M27) -> 65105699 | Q27: =IF(C27<>"", "CMH_01-CLM-" & TEXT(A27, "000"), "")
A28: 40 | B28: =العقد!A2 -> CMH_01-C01 | G28: =SUMIF('بنود المطالبات'!B$3:B$1805, A28, 'بنود المطالبات'!K$3:K$1805) -> 0 | H28: 100 | I28: =IFERROR(IF(G28<>0, G28*IF(H28<>"",H28,100)/100, 0), 0) -> 0 | J28: =IFERROR(IF(I28<>0, I28*IF(العقد!$M$2<>"",العقد!$M$2,0)/100, 0), 0) -> 0 | K28: =I28-J28 -> 0 | L28: =IFERROR(IF(K28<>0, K28*IF(العقد!$G$2<>"",العقد!$G$2,15)/100, 0), 0) -> 0 | M28: =K28+L28 -> 0 | N28: =SUMPRODUCT((O$3:O28="معتمدة")*M$3:M28) -> 65105699 | Q28: =IF(C28<>"", "CMH_01-CLM-" & TEXT(A28, "000"), "")
A29: 41 | B29: =العقد!A2 -> CMH_01-C01 | G29: =SUMIF('بنود المطالبات'!B$3:B$1805, A29, 'بنود المطالبات'!K$3:K$1805) -> 0 | H29: 100 | I29: =IFERROR(IF(G29<>0, G29*IF(H29<>"",H29,100)/100, 0), 0) -> 0 | J29: =IFERROR(IF(I29<>0, I29*IF(العقد!$M$2<>"",العقد!$M$2,0)/100, 0), 0) -> 0 | K29: =I29-J29 -> 0 | L29: =IFERROR(IF(K29<>0, K29*IF(العقد!$G$2<>"",العقد!$G$2,15)/100, 0), 0) -> 0 | M29: =K29+L29 -> 0 | N29: =SUMPRODUCT((O$3:O29="معتمدة")*M$3:M29) -> 65105699 | Q29: =IF(C29<>"", "CMH_01-CLM-" & TEXT(A29, "000"), "")
A30: 42 | B30: =العقد!A2 -> CMH_01-C01 | G30: =SUMIF('بنود المطالبات'!B$3:B$1805, A30, 'بنود المطالبات'!K$3:K$1805) -> 0 | H30: 100 | I30: =IFERROR(IF(G30<>0, G30*IF(H30<>"",H30,100)/100, 0), 0) -> 0 | J30: =IFERROR(IF(I30<>0, I30*IF(العقد!$M$2<>"",العقد!$M$2,0)/100, 0), 0) -> 0 | K30: =I30-J30 -> 0 | L30: =IFERROR(IF(K30<>0, K30*IF(العقد!$G$2<>"",العقد!$G$2,15)/100, 0), 0) -> 0 | M30: =K30+L30 -> 0 | N30: =SUMPRODUCT((O$3:O30="معتمدة")*M$3:M30) -> 65105699 | Q30: =IF(C30<>"", "CMH_01-CLM-" & TEXT(A30, "000"), "")
A31: 43 | B31: =العقد!A2 -> CMH_01-C01 | G31: =SUMIF('بنود المطالبات'!B$3:B$1805, A31, 'بنود المطالبات'!K$3:K$1805) -> 0 | H31: 100 | I31: =IFERROR(IF(G31<>0, G31*IF(H31<>"",H31,100)/100, 0), 0) -> 0 | J31: =IFERROR(IF(I31<>0, I31*IF(العقد!$M$2<>"",العقد!$M$2,0)/100, 0), 0) -> 0 | K31: =I31-J31 -> 0 | L31: =IFERROR(IF(K31<>0, K31*IF(العقد!$G$2<>"",العقد!$G$2,15)/100, 0), 0) -> 0 | M31: =K31+L31 -> 0 | N31: =SUMPRODUCT((O$3:O31="معتمدة")*M$3:M31) -> 65105699 | Q31: =IF(C31<>"", "CMH_01-CLM-" & TEXT(A31, "000"), "")
A32: 44 | B32: =العقد!A2 -> CMH_01-C01 | G32: =SUMIF('بنود المطالبات'!B$3:B$1805, A32, 'بنود المطالبات'!K$3:K$1805) -> 0 | H32: 100 | I32: =IFERROR(IF(G32<>0, G32*IF(H32<>"",H32,100)/100, 0), 0) -> 0 | J32: =IFERROR(IF(I32<>0, I32*IF(العقد!$M$2<>"",العقد!$M$2,0)/100, 0), 0) -> 0 | K32: =I32-J32 -> 0 | L32: =IFERROR(IF(K32<>0, K32*IF(العقد!$G$2<>"",العقد!$G$2,15)/100, 0), 0) -> 0 | M32: =K32+L32 -> 0 | N32: =SUMPRODUCT((O$3:O32="معتمدة")*M$3:M32) -> 65105699 | Q32: =IF(C32<>"", "CMH_01-CLM-" & TEXT(A32, "000"), "")
A33: 45 | B33: =العقد!A2 -> CMH_01-C01 | G33: =SUMIF('بنود المطالبات'!B$3:B$1805, A33, 'بنود المطالبات'!K$3:K$1805) -> 0 | H33: 100 | I33: =IFERROR(IF(G33<>0, G33*IF(H33<>"",H33,100)/100, 0), 0) -> 0 | J33: =IFERROR(IF(I33<>0, I33*IF(العقد!$M$2<>"",العقد!$M$2,0)/100, 0), 0) -> 0 | K33: =I33-J33 -> 0 | L33: =IFERROR(IF(K33<>0, K33*IF(العقد!$G$2<>"",العقد!$G$2,15)/100, 0), 0) -> 0 | M33: =K33+L33 -> 0 | N33: =SUMPRODUCT((O$3:O33="معتمدة")*M$3:M33) -> 65105699 | Q33: =IF(C33<>"", "CMH_01-CLM-" & TEXT(A33, "000"), "")
A34: 46 | B34: =العقد!A2 -> CMH_01-C01 | G34: =SUMIF('بنود المطالبات'!B$3:B$1805, A34, 'بنود المطالبات'!K$3:K$1805) -> 0 | H34: 100 | I34: =IFERROR(IF(G34<>0, G34*IF(H34<>"",H34,100)/100, 0), 0) -> 0 | J34: =IFERROR(IF(I34<>0, I34*IF(العقد!$M$2<>"",العقد!$M$2,0)/100, 0), 0) -> 0 | K34: =I34-J34 -> 0 | L34: =IFERROR(IF(K34<>0, K34*IF(العقد!$G$2<>"",العقد!$G$2,15)/100, 0), 0) -> 0 | M34: =K34+L34 -> 0 | N34: =SUMPRODUCT((O$3:O34="معتمدة")*M$3:M34) -> 65105699 | Q34: =IF(C34<>"", "CMH_01-CLM-" & TEXT(A34, "000"), "")
A35: 47 | B35: =العقد!A2 -> CMH_01-C01 | G35: =SUMIF('بنود المطالبات'!B$3:B$1805, A35, 'بنود المطالبات'!K$3:K$1805) -> 0 | H35: 100 | I35: =IFERROR(IF(G35<>0, G35*IF(H35<>"",H35,100)/100, 0), 0) -> 0 | J35: =IFERROR(IF(I35<>0, I35*IF(العقد!$M$2<>"",العقد!$M$2,0)/100, 0), 0) -> 0 | K35: =I35-J35 -> 0 | L35: =IFERROR(IF(K35<>0, K35*IF(العقد!$G$2<>"",العقد!$G$2,15)/100, 0), 0) -> 0 | M35: =K35+L35 -> 0 | N35: =SUMPRODUCT((O$3:O35="معتمدة")*M$3:M35) -> 65105699 | Q35: =IF(C35<>"", "CMH_01-CLM-" & TEXT(A35, "000"), "")
A36: 48 | B36: =العقد!A2 -> CMH_01-C01 | G36: =SUMIF('بنود المطالبات'!B$3:B$1805, A36, 'بنود المطالبات'!K$3:K$1805) -> 0 | H36: 100 | I36: =IFERROR(IF(G36<>0, G36*IF(H36<>"",H36,100)/100, 0), 0) -> 0 | J36: =IFERROR(IF(I36<>0, I36*IF(العقد!$M$2<>"",العقد!$M$2,0)/100, 0), 0) -> 0 | K36: =I36-J36 -> 0 | L36: =IFERROR(IF(K36<>0, K36*IF(العقد!$G$2<>"",العقد!$G$2,15)/100, 0), 0) -> 0 | M36: =K36+L36 -> 0 | N36: =SUMPRODUCT((O$3:O36="معتمدة")*M$3:M36) -> 65105699 | Q36: =IF(C36<>"", "CMH_01-CLM-" & TEXT(A36, "000"), "")
A37: 49 | B37: =العقد!A2 -> CMH_01-C01 | G37: =SUMIF('بنود المطالبات'!B$3:B$1805, A37, 'بنود المطالبات'!K$3:K$1805) -> 0 | H37: 100 | I37: =IFERROR(IF(G37<>0, G37*IF(H37<>"",H37,100)/100, 0), 0) -> 0 | J37: =IFERROR(IF(I37<>0, I37*IF(العقد!$M$2<>"",العقد!$M$2,0)/100, 0), 0) -> 0 | K37: =I37-J37 -> 0 | L37: =IFERROR(IF(K37<>0, K37*IF(العقد!$G$2<>"",العقد!$G$2,15)/100, 0), 0) -> 0 | M37: =K37+L37 -> 0 | N37: =SUMPRODUCT((O$3:O37="معتمدة")*M$3:M37) -> 65105699 | Q37: =IF(C37<>"", "CMH_01-CLM-" & TEXT(A37, "000"), "")
A38: 50 | B38: =العقد!A2 -> CMH_01-C01 | G38: =SUMIF('بنود المطالبات'!B$3:B$1805, A38, 'بنود المطالبات'!K$3:K$1805) -> 0 | H38: 100 | I38: =IFERROR(IF(G38<>0, G38*IF(H38<>"",H38,100)/100, 0), 0) -> 0 | J38: =IFERROR(IF(I38<>0, I38*IF(العقد!$M$2<>"",العقد!$M$2,0)/100, 0), 0) -> 0 | K38: =I38-J38 -> 0 | L38: =IFERROR(IF(K38<>0, K38*IF(العقد!$G$2<>"",العقد!$G$2,15)/100, 0), 0) -> 0 | M38: =K38+L38 -> 0 | N38: =SUMPRODUCT((O$3:O38="معتمدة")*M$3:M38) -> 65105699 | Q38: =IF(C38<>"", "CMH_01-CLM-" & TEXT(A38, "000"), "")

Sheet بنود المطالبات
A1: م | B1: رقم المطالبة | C1: رقم البند | D1: وصف البند (تلقائي) | E1: الوحدة (تلقائي) | F1: سعر الوحدة (تلقائي) | G1: الكمية التعاقدية (تلقائي) | H1: المنصرف السابق (تلقائي) | I1: كمية هذه الفترة | J1: التراكمي (تلقائي) | K1: مبلغ الفترة (تلقائي) | L1: نسبة الإنجاز % (تلقائي)
A2: 1 | B2: 1 | C2: 5 | D2: توريد وتركيب نظام إنذار — مثال | E2: عدد | F2: 45000 | G2: 50 | H2: 0 | I2: 10 | J2: 10 | K2: 450000 | L2: 20%
A3: 1 | B3: 1 | C3: 1 | D3: =IF(C3<>"", IFERROR(INDEX('بنود العقد'!B$3:B$388,C3), "⚠"), "") -> تشتمل على أعمال الهدم وإلإزالة والترحيل داخل أدوار المبنى والسعر يشمل نقل المخلفات الغير صالحه للمقالب العموميه ونقل المخلفات الصالحه لمخازن الجهه المالكه.Ref drawing: 07-MRA-DD-(as per floor number)-AR-001هدم وإزالة الجدران وتشمل جميع أنواع جدران الطوب والقواطع الجبسية و الخشبية و الزجاجية بحسب المخططات المعتمدة وتعليمات المهندس المشرف. | E3: =IF(C3<>"", IFERROR(INDEX('بنود العقد'!D$3:D$388,C3), ""), "") -> م2 | F3: =IF(C3<>"", IFERROR(INDEX('بنود العقد'!E$3:E$388,C3), 0), "") -> 18 | G3: =IF(C3<>"", IFERROR(INDEX('بنود العقد'!F$3:F$388,C3), 0), "") -> 17900 | H3: =IFERROR(SUMIFS(I$3:I$1805, B$3:B$1805, "<"&B3, C$3:C$1805, C3), 0) -> 0 | I3: 6940.6 | J3: =IF(I3<>"", H3+I3, 0) -> 6940.6 | K3: =IF(AND(I3<>"",F3<>""), I3*F3, "") -> 124930.8 | L3: =IF(AND(J3<>"",G3<>"",G3>0), J3/G3*100, "") -> 38.774302
A4: 2 | B4: 1 | C4: 2 | D4: =IF(C4<>"", IFERROR(INDEX('بنود العقد'!B$3:B$388,C4), "⚠"), "") -> تشتمل على أعمال الهدم وإلإزالة والترحيل داخل أدوار المبنى والسعر يشمل نقل المخلفات الغير صالحه للمقالب العموميه ونقل المخلفات الصالحه لمخازن الجهه المالكه.Ref drawing: 07-MRA-DD-(as per floor number)-AR-هدم وإزالة تشطيبات رخام أو بلاط بورسلان أو سيراميك للأرضيات والجدران الحالية بحسب المخططات المعتمدة وتعليمات المهندس المشرف. | E4: =IF(C4<>"", IFERROR(INDEX('بنود العقد'!D$3:D$388,C4), ""), "") -> م2 | F4: =IF(C4<>"", IFERROR(INDEX('بنود العقد'!E$3:E$388,C4), 0), "") -> 14.5 | G4: =IF(C4<>"", IFERROR(INDEX('بنود العقد'!F$3:F$388,C4), 0), "") -> 10362 | H4: =IFERROR(SUMIFS(I$3:I$1805, B$3:B$1805, "<"&B4, C$3:C$1805, C4), 0) -> 0 | I4: 2125.76 | J4: =IF(I4<>"", H4+I4, 0) -> 2125.76 | K4: =IF(AND(I4<>"",F4<>""), I4*F4, "") -> 30823.52 | L4: =IF(AND(J4<>"",G4<>"",G4>0), J4/G4*100, "") -> 20.514959
A5: 3 | B5: 1 | C5: 3 | D5: =IF(C5<>"", IFERROR(INDEX('بنود العقد'!B$3:B$388,C5), "⚠"), "") -> تشتمل على أعمال الهدم وإلإزالة والترحيل داخل أدوار المبنى والسعر يشمل نقل المخلفات الغير صالحه للمقالب العموميه ونقل المخلفات الصالحه لمخازن الجهه المالكهRef drawing: 07-MRA-DD-(as per floor number)-AR-001هدم وإزالة تشطيبات الأسقف المستعارة الحالية بما تشمل أسقف جبسية وبلاطات صناعية وأسقف معدنية بحسب المخططات المعتمدة وتعليمات المهندس المشرف. | E5: =IF(C5<>"", IFERROR(INDEX('بنود العقد'!D$3:D$388,C5), ""), "") -> م2 | F5: =IF(C5<>"", IFERROR(INDEX('بنود العقد'!E$3:E$388,C5), 0), "") -> 8.5 | G5: =IF(C5<>"", IFERROR(INDEX('بنود العقد'!F$3:F$388,C5), 0), "") -> 18420 | H5: =IFERROR(SUMIFS(I$3:I$1805, B$3:B$1805, "<"&B5, C$3:C$1805, C5), 0) -> 0 | I5: 3441.98 | J5: =IF(I5<>"", H5+I5, 0) -> 3441.98 | K5: =IF(AND(I5<>"",F5<>""), I5*F5, "") -> 29256.83 | L5: =IF(AND(J5<>"",G5<>"",G5>0), J5/G5*100, "") -> 18.686102
A6: 4 | B6: 1 | C6: 5 | D6: =IF(C6<>"", IFERROR(INDEX('بنود العقد'!B$3:B$388,C6), "⚠"), "") -> صبة أسمنتية كطبقة حماية للعزل في الأماكن الرطبة. ويشمل السعر وأي مواد أو أعمال يتطلبها تنفيذ العمل حسب المواصفات والمخططات وتعليمات المهندس المشرف. | E6: =IF(C6<>"", IFERROR(INDEX('بنود العقد'!D$3:D$388,C6), ""), "") -> م3 | F6: =IF(C6<>"", IFERROR(INDEX('بنود العقد'!E$3:E$388,C6), 0), "") -> 366 | G6: =IF(C6<>"", IFERROR(INDEX('بنود العقد'!F$3:F$388,C6), 0), "") -> 1345 | H6: =IFERROR(SUMIFS(I$3:I$1805, B$3:B$1805, "<"&B6, C$3:C$1805, C6), 0) -> 0 | I6: 37.48 | J6: =IF(I6<>"", H6+I6, 0) -> 37.48 | K6: =IF(AND(I6<>"",F6<>""), I6*F6, "") -> 13717.68 | L6: =IF(AND(J6<>"",G6<>"",G6>0), J6/G6*100, "") -> 2.7866171
A7: 5 | B7: 1 | C7: 6 | D7: =IF(C7<>"", IFERROR(INDEX('بنود العقد'!B$3:B$388,C7), "⚠"), "") -> توريد وبناء مباني من البلوك مقاوم للحريق شاملا المونة والفواصل وأربطة التثبيت والتسليح الرأسي وعتبات جميع الفتحات وعزل الجدران المزدوجة المفرّغة والمكملات ويتم توريد البلوك بالموقع على قواعد خشبية مغطاه بالبلاستيك ويستمر على هذه الحالة حتى يبدأ استخدامه للبناء على أن يكون ذو ابعاد بطول 40سم وسماكة حسب المطلوب وارتفاع 20سم وان تكون صلد سليم نظيف وذو زوايا خارجية قائمة يستعمل لبناء الحوائط حسب ما هو موضح بالمخططات مع التكحيل ويكون مطابق للمواصفات حسب النوعيه المطلوبة والسعر يشمل كل مايلزم للبناء من البلوك الكامل والقطع الخاصة سواء 5.0 أو 25.0 ، كذلك القطع الخاصة بتمديد المواسير بحيث لا يتم تكسير البلوك أثناء الاستخدام للبناء على الأطلاق ، بالإضافة إلى كافة المواد والاكسسوارات والسقايل واستعمال الشبك الممدد والتسليح بواسطة خوابير معدنية والمرابط المعدنية ويشمل السعر أي مواد أو أعمال يتطلبها استكمال العمل حسب المواصفات القسم Ref drawing: 07-MRA-DD-(as per floor number) وتعليمات المهندس المشرف 04200Ar-100 | E7: =IF(C7<>"", IFERROR(INDEX('بنود العقد'!D$3:D$388,C7), ""), "") -> م2 | F7: =IF(C7<>"", IFERROR(INDEX('بنود العقد'!E$3:E$388,C7), 0), "") -> 150 | G7: =IF(C7<>"", IFERROR(INDEX('بنود العقد'!F$3:F$388,C7), 0), "") -> 450 | H7: =IFERROR(SUMIFS(I$3:I$1805, B$3:B$1805, "<"&B7, C$3:C$1805, C7), 0) -> 0 | I7: 1288.91 | J7: =IF(I7<>"", H7+I7, 0) -> 1288.91 | K7: =IF(AND(I7<>"",F7<>""), I7*F7, "") -> 193336.5 | L7: =IF(AND(J7<>"",G7<>"",G7>0), J7/G7*100, "") -> 286.42444
A8: 6 | B8: 1 | C8: 7 | D8: =IF(C8<>"", IFERROR(INDEX('بنود العقد'!B$3:B$388,C8), "⚠"), "") -> توريد وبناء مباني من البلوك مقاوم للحريق شاملا المونة والفواصل وأربطة التثبيت والتسليح الرأسي وعتبات جميع الفتحات وعزل الجدران المزدوجة المفرّغة والمكملات ويتم توريد البلوك بالموقع علىقواعد خشبية مغطاه بالبلاستيك ويستمر على هذه الحالة حتى يبدأ استخدامه للبناء على أن يكون ذو ابعاد بطول 40سم وسماكة حسب المطلوب وارتفاع 20سم وان تكون صلد سليم نظيف وذو زوايا خارجية قائمة يستعمل لبناء الحوائط حسب ما هو موضح بالمخططات مع التكحيل ويكون مطابق للمواصفات حسب النوعيه المطلوبة والسعر يشمل كل مايلزم للبناء من البلوك الكامل والقطع الخاصة سواء 5.0 أو 25.0 ، كذلك القطع الخاصة بتمديد المواسير بحيث لا يتم تكسير البلوك أثناء الاستخدام للبناء على الأطلاق ، بالإضافة إلى كافة المواد والاكسسوارات والسقايل واستعمال الشبك الممدد والتسليح بواسطة خوابير معدنية والمرابط المعدنية ويشمل السعر أي مواد أو أعمال يتطلبها استكمال العمل حسب المواصفات القسمRef drawing: 07-MRA-DD-(as per floor number) وتعليمات المهندس المشرف 04200-Ar-100 | E8: =IF(C8<>"", IFERROR(INDEX('بنود العقد'!D$3:D$388,C8), ""), "") -> م2 | F8: =IF(C8<>"", IFERROR(INDEX('بنود العقد'!E$3:E$388,C8), 0), "") -> 150 | G8: =IF(C8<>"", IFERROR(INDEX('بنود العقد'!F$3:F$388,C8), 0), "") -> 76 | H8: =IFERROR(SUMIFS(I$3:I$1805, B$3:B$1805, "<"&B8, C$3:C$1805, C8), 0) -> 0 | I8: 117.36 | J8: =IF(I8<>"", H8+I8, 0) -> 117.36 | K8: =IF(AND(I8<>"",F8<>""), I8*F8, "") -> 17604 | L8: =IF(AND(J8<>"",G8<>"",G8>0), J8/G8*100, "") -> 154.42105
A9: 7 | B9: 1 | C9: 72 | D9: =IF(C9<>"", IFERROR(INDEX('بنود العقد'!B$3:B$388,C9), "⚠"), "") -> طبقة من اللياسة الأسمنتية فوق الأسطح الخرسانية والجدران الداخلية بسمك متوسط 20 مم على طبقات طرطشة بسمك 5 مم وضهارة 15 مم حسب المواصفات مع المعالجة اليومية بالمياه لمنع التنميلات ويتم عمل افريز بين البلوك والخرسانة يملئ بمواد قابلة للدهان والسعر يشمل كامل الأكسسوارات اللازمة من شبك معدني ممدد وزوايا ونهايات معدنية ومواد الترابط وعمل تجاويف في طبقة اللياسة بعمق 10مم عرض 10مم في الاعمدة وفي الجدران ان وجدت حسب الرسومات والمناظير وتعليمات المهندس المشرف ذلك حسب الاصول الفنية وتعليمات المهندس المشرف. لياسة الجدران والأعمدة الداخلية وتشمل جميع الإكسسوارات بإرتفاع 20 سم أعلي الأسقف الجبسيه لزوم الجدران الداخلية | E9: =IF(C9<>"", IFERROR(INDEX('بنود العقد'!D$3:D$388,C9), ""), "") -> م² | F9: =IF(C9<>"", IFERROR(INDEX('بنود العقد'!E$3:E$388,C9), 0), "") -> 42 | G9: =IF(C9<>"", IFERROR(INDEX('بنود العقد'!F$3:F$388,C9), 0), "") -> 758 | H9: =IFERROR(SUMIFS(I$3:I$1805, B$3:B$1805, "<"&B9, C$3:C$1805, C9), 0) -> 0 | I9: 1521.25 | J9: =IF(I9<>"", H9+I9, 0) -> 1521.25 | K9: =IF(AND(I9<>"",F9<>""), I9*F9, "") -> 63892.5 | L9: =IF(AND(J9<>"",G9<>"",G9>0), J9/G9*100, "") -> 200.69261
A10: 8 | B10: 1 | C10: 74 | D10: =IF(C10<>"", IFERROR(INDEX('بنود العقد'!B$3:B$388,C10), "⚠"), "") -> توريد وتركيب قاطع جداري ثخانة 100مم ذو الواح جبسية مقاومه للحريق ثخانة 5.12مم تركب من الجهتين )طبقات مزدوجة( يشمل المسامير المعدنية و المزالج / الأعضاء المعدنية الساندة والسكك والغطاء العازل للصوت )صوف صخري( وكل الإكسسوارات حسب المخطط والمواصفات وتعليمات المهندس المشرف. | E10: =IF(C10<>"", IFERROR(INDEX('بنود العقد'!D$3:D$388,C10), ""), "") -> م² | F10: =IF(C10<>"", IFERROR(INDEX('بنود العقد'!E$3:E$388,C10), 0), "") -> 180 | G10: =IF(C10<>"", IFERROR(INDEX('بنود العقد'!F$3:F$388,C10), 0), "") -> 12526 | H10: =IFERROR(SUMIFS(I$3:I$1805, B$3:B$1805, "<"&B10, C$3:C$1805, C10), 0) -> 0 | I10: 356.6 | J10: =IF(I10<>"", H10+I10, 0) -> 356.6 | K10: =IF(AND(I10<>"",F10<>""), I10*F10, "") -> 64188 | L10: =IF(AND(J10<>"",G10<>"",G10>0), J10/G10*100, "") -> 2.8468785
A11: 9 | B11: 1 | C11: 254 | D11: =IF(C11<>"", IFERROR(INDEX('بنود العقد'!B$3:B$388,C11), "⚠"), "") -> توريد وتركيب وإختبار وفحص علبة خدمة من نوعية ممتازة تحتوى على ) أ ( مقابس تغذية أرضية مزدوجة ذات أسلاك 4 مم2 كحد أدنى مركبة على الأرض وتشمل أسلاك التأريض من اللوحة حتى المقابس + )ب( مآخذ للهاتف والبيانات ذات كابلات CAT 6A UTP وحتى كابينة الداتا وحسب مواصفات إدارة الـ IT بالوزارة. على المقاول المعاينة و فحص الشبكة الحالية و الاستفادة من التمديدات الحالية و دمجها مع التركيبات الجديدة بعد عمل الاختبارات اللازمة و بعد الموافقة من مهندس المشرف . النوع )A( )تحتوى على 4 قوى & 4 داتا ( | E11: =IF(C11<>"", IFERROR(INDEX('بنود العقد'!D$3:D$388,C11), ""), "") -> عدد | F11: =IF(C11<>"", IFERROR(INDEX('بنود العقد'!E$3:E$388,C11), 0), "") -> 2160 | G11: =IF(C11<>"", IFERROR(INDEX('بنود العقد'!F$3:F$388,C11), 0), "") -> 286 | H11: =IFERROR(SUMIFS(I$3:I$1805, B$3:B$1805, "<"&B11, C$3:C$1805, C11), 0) -> 0 | I11: 30 | J11: =IF(I11<>"", H11+I11, 0) -> 30 | K11: =IF(AND(I11<>"",F11<>""), I11*F11, "") -> 64800 | L11: =IF(AND(J11<>"",G11<>"",G11>0), J11/G11*100, "") -> 10.48951
A12: 10 | B12: 1 | C12: 255 | D12: =IF(C12<>"", IFERROR(INDEX('بنود العقد'!B$3:B$388,C12), "⚠"), "") -> توريد وتركيب وإختبار وفحص علبة خدمة من نوعية ممتازة تحتوى على ) أ ( مقابس تغذية أرضية مزدوجة ذات أسلاك 4 مم2 كحد أدنى مركبة على الأرض وتشمل أسلاك التأريض من اللوحة حتى المقابس + )ب( مآخذ للهاتف والبيانات ذات كابلات CAT 6A UTP وحتى كابينة الداتا وحسب مواصفات إدارة الـ IT بالوزارة. على المقاول المعاينة و فحص الشبكة الحالية و الاستفادة من التمديدات الحالية و دمجها مع التركيبات الجديدة بعد عمل الاختبارات اللازمة و بعد الموافقة من مهندس المشرف . النوع )B( )تحتوى على 2 قوى & 2 داتا ( | E12: =IF(C12<>"", IFERROR(INDEX('بنود العقد'!D$3:D$388,C12), ""), "") -> عدد | F12: =IF(C12<>"", IFERROR(INDEX('بنود العقد'!E$3:E$388,C12), 0), "") -> 1800 | G12: =IF(C12<>"", IFERROR(INDEX('بنود العقد'!F$3:F$388,C12), 0), "") -> 20 | H12: =IFERROR(SUMIFS(I$3:I$1805, B$3:B$1805, "<"&B12, C$3:C$1805, C12), 0) -> 0 | I12: 19 | J12: =IF(I12<>"", H12+I12, 0) -> 19 | K12: =IF(AND(I12<>"",F12<>""), I12*F12, "") -> 34200 | L12: =IF(AND(J12<>"",G12<>"",G12>0), J12/G12*100, "") -> 95
A13: 11 | B13: 1 | C13: 256 | D13: =IF(C13<>"", IFERROR(INDEX('بنود العقد'!B$3:B$388,C13), "⚠"), "") -> توريد وتركيب وإختبار وفحص علبة خدمة من نوعية ممتازة تحتوى على ) أ ( مقابس تغذية أرضية مزدوجة ذات أسلاك 4 مم2 كحد أدنى مركبة على الأرض وتشمل أسلاك التأريض من اللوحة حتى المقابس + )ب( مآخذ للهاتف والبيانات ذات كابلات CAT 6A UTP وحتى كابينة الداتا وحسب مواصفات إدارة الـ IT بالوزارة. على المقاول المعاينة و فحص الشبكة الحالية و الاستفادة من التمديدات الحالية و دمجها مع التركيبات الجديدة بعد عمل الاختبارات اللازمة و بعد الموافقة من مهندس المشرف . النوع )1FB( )تحتوى على 1 قوى ( | E13: =IF(C13<>"", IFERROR(INDEX('بنود العقد'!D$3:D$388,C13), ""), "") -> عدد | F13: =IF(C13<>"", IFERROR(INDEX('بنود العقد'!E$3:E$388,C13), 0), "") -> 720 | G13: =IF(C13<>"", IFERROR(INDEX('بنود العقد'!F$3:F$388,C13), 0), "") -> 141 | H13: =IFERROR(SUMIFS(I$3:I$1805, B$3:B$1805, "<"&B13, C$3:C$1805, C13), 0) -> 0 | I13: 9 | J13: =IF(I13<>"", H13+I13, 0) -> 9 | K13: =IF(AND(I13<>"",F13<>""), I13*F13, "") -> 6480 | L13: =IF(AND(J13<>"",G13<>"",G13>0), J13/G13*100, "") -> 6.3829787
A14: 12 | B14: 2 | C14: 5 | D14: =IF(C14<>"", IFERROR(INDEX('بنود العقد'!B$3:B$388,C14), "⚠"), "") -> صبة أسمنتية كطبقة حماية للعزل في الأماكن الرطبة. ويشمل السعر وأي مواد أو أعمال يتطلبها تنفيذ العمل حسب المواصفات والمخططات وتعليمات المهندس المشرف. | E14: =IF(C14<>"", IFERROR(INDEX('بنود العقد'!D$3:D$388,C14), ""), "") -> م3 | F14: =IF(C14<>"", IFERROR(INDEX('بنود العقد'!E$3:E$388,C14), 0), "") -> 366 | G14: =IF(C14<>"", IFERROR(INDEX('بنود العقد'!F$3:F$388,C14), 0), "") -> 1345 | H14: =IFERROR(SUMIFS(I$3:I$1805, B$3:B$1805, "<"&B14, C$3:C$1805, C14), 0) -> 37.48 | I14: 39.91 | J14: =IF(I14<>"", H14+I14, 0) -> 77.39 | K14: =IF(AND(I14<>"",F14<>""), I14*F14, "") -> 14607.06 | L14: =IF(AND(J14<>"",G14<>"",G14>0), J14/G14*100, "") -> 5.7539033
... A1564: 1562 | B1564: 21 | C1564: 369 | D1564: =IF(C1564<>"", IFERROR(INDEX('بنود العقد'!B$3:B$388,C1564), "⚠"), "") -> توريد وتركيب صندوق غاطس يوضع بداخله محبس LANDING VALVE | E1564: =IF(C1564<>"", IFERROR(INDEX('بنود العقد'!D$3:D$388,C1564), ""), "") -> عدد | F1564: =IF(C1564<>"", IFERROR(INDEX('بنود العقد'!E$3:E$388,C1564), 0), "") -> 1176 | G1564: =IF(C1564<>"", IFERROR(INDEX('بنود العقد'!F$3:F$388,C1564), 0), "") -> 0 | H1564: =IFERROR(SUMIFS(I$3:I$1805, B$3:B$1805, "<"&B1564, C$3:C$1805, C1564), 0) -> 27 | I1564: 5 | J1564: =IF(I1564<>"", H1564+I1564, 0) -> 32 | K1564: =IF(AND(I1564<>"",F1564<>""), I1564*F1564, "") -> 5880 | L1564: =IF(AND(J1564<>"",G1564<>"",G1564>0), J1564/G1564*100, "")
A1565: 1563 | B1565: 21 | D1565: =IF(C1565<>"", IFERROR(INDEX('بنود العقد'!B$3:B$388,C1565), "⚠"), "") | E1565: =IF(C1565<>"", IFERROR(INDEX('بنود العقد'!D$3:D$388,C1565), ""), "") | F1565: =IF(C1565<>"", IFERROR(INDEX('بنود العقد'!E$3:E$388,C1565), 0), "") | G1565: =IF(C1565<>"", IFERROR(INDEX('بنود العقد'!F$3:F$388,C1565), 0), "") | H1565: =IFERROR(SUMIFS(I$3:I$1805, B$3:B$1805, "<"&B1565, C$3:C$1805, C1565), 0) -> 0 | J1565: =IF(I1565<>"", H1565+I1565, 0) -> 0 | K1565: =IF(AND(I1565<>"",F1565<>""), I1565*F1565, "") | L1565: =IF(AND(J1565<>"",G1565<>"",G1565>0), J1565/G1565*100, "")
A1566: 1564 | B1566: 21 | D1566: =IF(C1566<>"", IFERROR(INDEX('بنود العقد'!B$3:B$388,C1566), "⚠"), "") | E1566: =IF(C1566<>"", IFERROR(INDEX('بنود العقد'!D$3:D$388,C1566), ""), "") | F1566: =IF(C1566<>"", IFERROR(INDEX('بنود العقد'!E$3:E$388,C1566), 0), "") | G1566: =IF(C1566<>"", IFERROR(INDEX('بنود العقد'!F$3:F$388,C1566), 0), "") | H1566: =IFERROR(SUMIFS(I$3:I$1805, B$3:B$1805, "<"&B1566, C$3:C$1805, C1566), 0) -> 0 | J1566: =IF(I1566<>"", H1566+I1566, 0) -> 0 | K1566: =IF(AND(I1566<>"",F1566<>""), I1566*F1566, "") | L1566: =IF(AND(J1566<>"",G1566<>"",G1566>0), J1566/G1566*100, "")
A1567: 1565 | B1567: 21 | D1567: =IF(C1567<>"", IFERROR(INDEX('بنود العقد'!B$3:B$388,C1567), "⚠"), "") | E1567: =IF(C1567<>"", IFERROR(INDEX('بنود العقد'!D$3:D$388,C1567), ""), "") | F1567: =IF(C1567<>"", IFERROR(INDEX('بنود العقد'!E$3:E$388,C1567), 0), "") | G1567: =IF(C1567<>"", IFERROR(INDEX('بنود العقد'!F$3:F$388,C1567), 0), "") | H1567: =IFERROR(SUMIFS(I$3:I$1805, B$3:B$1805, "<"&B1567, C$3:C$1805, C1567), 0) -> 0 | J1567: =IF(I1567<>"", H1567+I1567, 0) -> 0 | K1567: =IF(AND(I1567<>"",F1567<>""), I1567*F1567, "") | L1567: =IF(AND(J1567<>"",G1567<>"",G1567>0), J1567/G1567*100, "")
A1568: 1566 | B1568: 21 | D1568: =IF(C1568<>"", IFERROR(INDEX('بنود العقد'!B$3:B$388,C1568), "⚠"), "") | E1568: =IF(C1568<>"", IFERROR(INDEX('بنود العقد'!D$3:D$388,C1568), ""), "") | F1568: =IF(C1568<>"", IFERROR(INDEX('بنود العقد'!E$3:E$388,C1568), 0), "") | G1568: =IF(C1568<>"", IFERROR(INDEX('بنود العقد'!F$3:F$388,C1568), 0), "") | H1568: =IFERROR(SUMIFS(I$3:I$1805, B$3:B$1805, "<"&B1568, C$3:C$1805, C1568), 0) -> 0 | J1568: =IF(I1568<>"", H1568+I1568, 0) -> 0 | K1568: =IF(AND(I1568<>"",F1568<>""), I1568*F1568, "") | L1568: =IF(AND(J1568<>"",G1568<>"",G1568>0), J1568/G1568*100, "")
A1569: 1567 | B1569: 21 | D1569: =IF(C1569<>"", IFERROR(INDEX('بنود العقد'!B$3:B$388,C1569), "⚠"), "") | E1569: =IF(C1569<>"", IFERROR(INDEX('بنود العقد'!D$3:D$388,C1569), ""), "") | F1569: =IF(C1569<>"", IFERROR(INDEX('بنود العقد'!E$3:E$388,C1569), 0), "") | G1569: =IF(C1569<>"", IFERROR(INDEX('بنود العقد'!F$3:F$388,C1569), 0), "") | H1569: =IFERROR(SUMIFS(I$3:I$1805, B$3:B$1805, "<"&B1569, C$3:C$1805, C1569), 0) -> 0 | J1569: =IF(I1569<>"", H1569+I1569, 0) -> 0 | K1569: =IF(AND(I1569<>"",F1569<>""), I1569*F1569, "") | L1569: =IF(AND(J1569<>"",G1569<>"",G1569>0), J1569/G1569*100, "")
A1570: 1568 | B1570: 21 | D1570: =IF(C1570<>"", IFERROR(INDEX('بنود العقد'!B$3:B$388,C1570), "⚠"), "") | E1570: =IF(C1570<>"", IFERROR(INDEX('بنود العقد'!D$3:D$388,C1570), ""), "") | F1570: =IF(C1570<>"", IFERROR(INDEX('بنود العقد'!E$3:E$388,C1570), 0), "") | G1570: =IF(C1570<>"", IFERROR(INDEX('بنود العقد'!F$3:F$388,C1570), 0), "") | H1570: =IFERROR(SUMIFS(I$3:I$1805, B$3:B$1805, "<"&B1570, C$3:C$1805, C1570), 0) -> 0 | J1570: =IF(I1570<>"", H1570+I1570, 0) -> 0 | K1570: =IF(AND(I1570<>"",F1570<>""), I1570*F1570, "") | L1570: =IF(AND(J1570<>"",G1570<>"",G1570>0), J1570/G1570*100, "")
A1571: 1569 | B1571: 21 | D1571: =IF(C1571<>"", IFERROR(INDEX('بنود العقد'!B$3:B$388,C1571), "⚠"), "") | E1571: =IF(C1571<>"", IFERROR(INDEX('بنود العقد'!D$3:D$388,C1571), ""), "") | F1571: =IF(C1571<>"", IFERROR(INDEX('بنود العقد'!E$3:E$388,C1571), 0), "") | G1571: =IF(C1571<>"", IFERROR(INDEX('بنود العقد'!F$3:F$388,C1571), 0), "") | H1571: =IFERROR(SUMIFS(I$3:I$1805, B$3:B$1805, "<"&B1571, C$3:C$1805, C1571), 0) -> 0 | J1571: =IF(I1571<>"", H1571+I1571, 0) -> 0 | K1571: =IF(AND(I1571<>"",F1571<>""), I1571*F1571, "") | L1571: =IF(AND(J1571<>"",G1571<>"",G1571>0), J1571/G1571*100, "")
A1572: 1570 | B1572: 21 | D1572: =IF(C1572<>"", IFERROR(INDEX('بنود العقد'!B$3:B$388,C1572), "⚠"), "") | E1572: =IF(C1572<>"", IFERROR(INDEX('بنود العقد'!D$3:D$388,C1572), ""), "") | F1572: =IF(C1572<>"", IFERROR(INDEX('بنود العقد'!E$3:E$388,C1572), 0), "") | G1572: =IF(C1572<>"", IFERROR(INDEX('بنود العقد'!F$3:F$388,C1572), 0), "") | H1572: =IFERROR(SUMIFS(I$3:I$1805, B$3:B$1805, "<"&B1572, C$3:C$1805, C1572), 0) -> 0 | J1572: =IF(I1572<>"", H1572+I1572, 0) -> 0 | K1572: =IF(AND(I1572<>"",F1572<>""), I1572*F1572, "") | L1572: =IF(AND(J1572<>"",G1572<>"",G1572>0), J1572/G1572*100, "")
A1573: 1571 | B1573: 21 | D1573: =IF(C1573<>"", IFERROR(INDEX('بنود العقد'!B$3:B$388,C1573), "⚠"), "") | E1573: =IF(C1573<>"", IFERROR(INDEX('بنود العقد'!D$3:D$388,C1573), ""), "") | F1573: =IF(C1573<>"", IFERROR(INDEX('بنود العقد'!E$3:E$388,C1573), 0), "") | G1573: =IF(C1573<>"", IFERROR(INDEX('بنود العقد'!F$3:F$388,C1573), 0), "") | H1573: =IFERROR(SUMIFS(I$3:I$1805, B$3:B$1805, "<"&B1573, C$3:C$1805, C1573), 0) -> 0 | J1573: =IF(I1573<>"", H1573+I1573, 0) -> 0 | K1573: =IF(AND(I1573<>"",F1573<>""), I1573*F1573, "") | L1573: =IF(AND(J1573<>"",G1573<>"",G1573>0), J1573/G1573*100, "")
A1574: 1572 | B1574: 21 | D1574: =IF(C1574<>"", IFERROR(INDEX('بنود العقد'!B$3:B$388,C1574), "⚠"), "") | E1574: =IF(C1574<>"", IFERROR(INDEX('بنود العقد'!D$3:D$388,C1574), ""), "") | F1574: =IF(C1574<>"", IFERROR(INDEX('بنود العقد'!E$3:E$388,C1574), 0), "") | G1574: =IF(C1574<>"", IFERROR(INDEX('بنود العقد'!F$3:F$388,C1574), 0), "") | H1574: =IFERROR(SUMIFS(I$3:I$1805, B$3:B$1805, "<"&B1574, C$3:C$1805, C1574), 0) -> 0 | J1574: =IF(I1574<>"", H1574+I1574, 0) -> 0 | K1574: =IF(AND(I1574<>"",F1574<>""), I1574*F1574, "") | L1574: =IF(AND(J1574<>"",G1574<>"",G1574>0), J1574/G1574*100, "")
A1575: 1573 | B1575: 21 | D1575: =IF(C1575<>"", IFERROR(INDEX('بنود العقد'!B$3:B$388,C1575), "⚠"), "") | E1575: =IF(C1575<>"", IFERROR(INDEX('بنود العقد'!D$3:D$388,C1575), ""), "") | F1575: =IF(C1575<>"", IFERROR(INDEX('بنود العقد'!E$3:E$388,C1575), 0), "") | G1575: =IF(C1575<>"", IFERROR(INDEX('بنود العقد'!F$3:F$388,C1575), 0), "") | H1575: =IFERROR(SUMIFS(I$3:I$1805, B$3:B$1805, "<"&B1575, C$3:C$1805, C1575), 0) -> 0 | J1575: =IF(I1575<>"", H1575+I1575, 0) -> 0 | K1575: =IF(AND(I1575<>"",F1575<>""), I1575*F1575, "") | L1575: =IF(AND(J1575<>"",G1575<>"",G1575>0), J1575/G1575*100, "")
A1576: 1574 | B1576: 21 | D1576: =IF(C1576<>"", IFERROR(INDEX('بنود العقد'!B$3:B$388,C1576), "⚠"), "") | E1576: =IF(C1576<>"", IFERROR(INDEX('بنود العقد'!D$3:D$388,C1576), ""), "") | F1576: =IF(C1576<>"", IFERROR(INDEX('بنود العقد'!E$3:E$388,C1576), 0), "") | G1576: =IF(C1576<>"", IFERROR(INDEX('بنود العقد'!F$3:F$388,C1576), 0), "") | H1576: =IFERROR(SUMIFS(I$3:I$1805, B$3:B$1805, "<"&B1576, C$3:C$1805, C1576), 0) -> 0 | J1576: =IF(I1576<>"", H1576+I1576, 0) -> 0 | K1576: =IF(AND(I1576<>"",F1576<>""), I1576*F1576, "") | L1576: =IF(AND(J1576<>"",G1576<>"",G1576>0), J1576/G1576*100, "")
... A1805: 1480 | B1805: 17 | D1805: =IF(C1805<>"", IFERROR(INDEX('بنود العقد'!B$3:B$388,C1805), "⚠"), "") | E1805: =IF(C1805<>"", IFERROR(INDEX('بنود العقد'!D$3:D$388,C1805), ""), "") | F1805: =IF(C1805<>"", IFERROR(INDEX('بنود العقد'!E$3:E$388,C1805), 0), "") | G1805: =IF(C1805<>"", IFERROR(INDEX('بنود العقد'!F$3:F$388,C1805), 0), "") | H1805: =IFERROR(SUMIFS(I$3:I$1805, B$3:B$1805, "<"&B1805, C$3:C$1805, C1805), 0) -> 0 | J1805: =IF(I1805<>"", H1805+I1805, 0) -> 0 | K1805: =IF(AND(I1805<>"",F1805<>""), I1805*F1805, "") | L1805: =IF(AND(J1805<>"",G1805<>"",G1805>0), J1805/G1805*100, "")

Sheet الملخص التراكمي
A1: 📊 الملخص التراكمي — CMH_01
A2: رقم البند | B2: وصف البند (تلقائي) | C2: الفئة (تلقائي) | D2: الكمية التعاقدية (تلقائي) | E2: المنصرف التراكمي (تلقائي) | F2: المبلغ التراكمي (تلقائي) | G2: المتبقي كمية (تلقائي) | H2: المتبقي مبلغ (تلقائي) | I2: نسبة الإنجاز % (تلقائي)
A3: 1 | B3: =IF('بنود العقد'!B3<>"", 'بنود العقد'!B3, "") -> تشتمل على أعمال الهدم وإلإزالة والترحيل داخل أدوار المبنى والسعر يشمل نقل المخلفات الغير صالحه للمقالب العموميه ونقل المخلفات الصالحه لمخازن الجهه المالكه.Ref drawing: 07-MRA-DD-(as per floor number)-AR-001هدم وإزالة الجدران وتشمل جميع أنواع جدران الطوب والقواطع الجبسية و الخشبية و الزجاجية بحسب المخططات المعتمدة وتعليمات المهندس المشرف. | C3: =IF('بنود العقد'!C3<>"", 'بنود العقد'!C3, "") -> معماري | D3: =IF('بنود العقد'!F3<>"", 'بنود العقد'!F3, "") -> 17900 | E3: =IF(B3<>"", SUMPRODUCT(('بنود المطالبات'!C$3:C$1805=A3)*'بنود المطالبات'!I$3:I$1805), "") -> 16098.97 | F3: =IFERROR(IF(AND(E3<>"",'بنود العقد'!E3<>""), E3*'بنود العقد'!E3, 0), 0) -> 289781.46 | G3: =IF(AND(D3<>"",E3<>""), D3-E3, "") -> 1801.03 | H3: =IF(AND('بنود العقد'!G3<>"",F3<>""), 'بنود العقد'!G3-F3, "") -> 32418.54 | I3: =IFERROR(IF(AND(E3<>"",D3<>"",D3>0), MIN(E3/D3*100, 100), 0), 0) -> 89.93838
A4: 2 | B4: =IF('بنود العقد'!B4<>"", 'بنود العقد'!B4, "") -> تشتمل على أعمال الهدم وإلإزالة والترحيل داخل أدوار المبنى والسعر يشمل نقل المخلفات الغير صالحه للمقالب العموميه ونقل المخلفات الصالحه لمخازن الجهه المالكه.Ref drawing: 07-MRA-DD-(as per floor number)-AR-هدم وإزالة تشطيبات رخام أو بلاط بورسلان أو سيراميك للأرضيات والجدران الحالية بحسب المخططات المعتمدة وتعليمات المهندس المشرف. | C4: =IF('بنود العقد'!C4<>"", 'بنود العقد'!C4, "") -> معماري | D4: =IF('بنود العقد'!F4<>"", 'بنود العقد'!F4, "") -> 10362 | E4: =IF(B4<>"", SUMPRODUCT(('بنود المطالبات'!C$3:C$1805=A4)*'بنود المطالبات'!I$3:I$1805), "") -> 4854.36 | F4: =IFERROR(IF(AND(E4<>"",'بنود العقد'!E4<>""), E4*'بنود العقد'!E4, 0), 0) -> 70388.22 | G4: =IF(AND(D4<>"",E4<>""), D4-E4, "") -> 5507.64 | H4: =IF(AND('بنود العقد'!G4<>"",F4<>""), 'بنود العقد'!G4-F4, "") -> 79860.78 | I4: =IFERROR(IF(AND(E4<>"",D4<>"",D4>0), MIN(E4/D4*100, 100), 0), 0) -> 46.847713
A5: 3 | B5: =IF('بنود العقد'!B5<>"", 'بنود العقد'!B5, "") -> تشتمل على أعمال الهدم وإلإزالة والترحيل داخل أدوار المبنى والسعر يشمل نقل المخلفات الغير صالحه للمقالب العموميه ونقل المخلفات الصالحه لمخازن الجهه المالكهRef drawing: 07-MRA-DD-(as per floor number)-AR-001هدم وإزالة تشطيبات الأسقف المستعارة الحالية بما تشمل أسقف جبسية وبلاطات صناعية وأسقف معدنية بحسب المخططات المعتمدة وتعليمات المهندس المشرف. | C5: =IF('بنود العقد'!C5<>"", 'بنود العقد'!C5, "") -> معماري | D5: =IF('بنود العقد'!F5<>"", 'بنود العقد'!F5, "") -> 18420 | E5: =IF(B5<>"", SUMPRODUCT(('بنود المطالبات'!C$3:C$1805=A5)*'بنود المطالبات'!I$3:I$1805), "") -> 16845.64 | F5: =IFERROR(IF(AND(E5<>"",'بنود العقد'!E5<>""), E5*'بنود العقد'!E5, 0), 0) -> 143187.94 | G5: =IF(AND(D5<>"",E5<>""), D5-E5, "") -> 1574.36 | H5: =IF(AND('بنود العقد'!G5<>"",F5<>""), 'بنود العقد'!G5-F5, "") -> 13382.06 | I5: =IFERROR(IF(AND(E5<>"",D5<>"",D5>0), MIN(E5/D5*100, 100), 0), 0) -> 91.452986
A6: 4 | B6: =IF('بنود العقد'!B6<>"", 'بنود العقد'!B6, "") -> صبة خرسانية مع شبكة حديد بقطر 8 مم بأبعاد 10*10 سم مخدومة بالمسطرين والقدة لتعطي سطحا ناعما في الفناء الوسطي. ويشمل السعر الدفان وأي مواد أو أعمال يتطلبها تنفيذ العمل حسب المواصفات والمخططات وتعليمات المهندس المشرف. | C6: =IF('بنود العقد'!C6<>"", 'بنود العقد'!C6, "") -> مدني | D6: =IF('بنود العقد'!F6<>"", 'بنود العقد'!F6, "") -> 6 | E6: =IF(B6<>"", SUMPRODUCT(('بنود المطالبات'!C$3:C$1805=A6)*'بنود المطالبات'!I$3:I$1805), "") -> 6.34 | F6: =IFERROR(IF(AND(E6<>"",'بنود العقد'!E6<>""), E6*'بنود العقد'!E6, 0), 0) -> 3423.6 | G6: =IF(AND(D6<>"",E6<>""), D6-E6, "") -> -0.34 | H6: =IF(AND('بنود العقد'!G6<>"",F6<>""), 'بنود العقد'!G6-F6, "") -> -183.6 | I6: =IFERROR(IF(AND(E6<>"",D6<>"",D6>0), MIN(E6/D6*100, 100), 0), 0) -> 100
A7: 5 | B7: =IF('بنود العقد'!B7<>"", 'بنود العقد'!B7, "") -> صبة أسمنتية كطبقة حماية للعزل في الأماكن الرطبة. ويشمل السعر وأي مواد أو أعمال يتطلبها تنفيذ العمل حسب المواصفات والمخططات وتعليمات المهندس المشرف. | C7: =IF('بنود العقد'!C7<>"", 'بنود العقد'!C7, "") -> مدني | D7: =IF('بنود العقد'!F7<>"", 'بنود العقد'!F7, "") -> 1345 | E7: =IF(B7<>"", SUMPRODUCT(('بنود المطالبات'!C$3:C$1805=A7)*'بنود المطالبات'!I$3:I$1805), "") -> 406.32 | F7: =IFERROR(IF(AND(E7<>"",'بنود العقد'!E7<>""), E7*'بنود العقد'!E7, 0), 0) -> 148713.12 | G7: =IF(AND(D7<>"",E7<>""), D7-E7, "") -> 938.68 | H7: =IF(AND('بنود العقد'!G7<>"",F7<>""), 'بنود العقد'!G7-F7, "") -> 343556.88 | I7: =IFERROR(IF(AND(E7<>"",D7<>"",D7>0), MIN(E7/D7*100, 100), 0), 0) -> 30.209665
